Workbook

Sheet Sheet1
A1: Season | B1: Round | C1: Age | D1: Location | E1: Replicate | F1: % moisture | G1: Wet weight g | H1: Dry weight (g) | I1: Dry weight (g/cm2) | J1: Dry weight (g/m2) | K1: Protein g/100g dry weight | L1: Protein g/100g wet weight | M1: fat g/100g dry weight | N1: fat g/100g wet weight | O1: fat mg/g dry weight | P1: fat mg/g wet weight | Q1: total fat (g/cm2) | R1: protein g/cm2 | S1: fat g/m2 | T1: protein g/m2 | U1: No. of days | V1: average dry weight accumulation (g/m2/day) | W1: average daily fat accumulation (g/m2/day) | X1: average daily protein accumulation (g/m2/day)
A2: 1 | B2: 1 | C2: 1 | D2: 1 | E2: A | F2: 87.5 | G2: 6.0084 | H2: 0.753 | I2: =H2/1875 -> 0.0004016 | J2: =I2*10000 -> 4.016 | K2: 5 | L2: 0.6 | M2: 0.72 | N2: 0.09 | O2: 7.2 | P2: 0.9 | Q2: =((M2/100)*H2)/1875 -> 2.89152e-06 | R2: =((K2/100)*H2)/1875 -> 2.008e-05 | S2: =Q2*10000 -> 0.0289152 | T2: =R2*10000 -> 0.2008 | U2: 13 | V2: =J2/U2 -> 0.30892308 | W2: =S2/U2 -> 0.0022242462 | X2: =T2/U2 -> 0.015446154
A3: 1 | B3: 1 | C3: 1 | D3: 1 | E3: B | F3: 79.1 | G3: 4.5179 | H3: 0.9429 | I3: =H3/1875 -> 0.00050288 | J3: =I3*10000 -> 5.0288 | K3: 3.9 | L3: 0.8 | M3: 0.63 | N3: 0.13 | O3: 6.3 | P3: 1.3 | Q3: =((M3/100)*H3)/1875 -> 3.168144e-06 | R3: =((K3/100)*H3)/1875 -> 1.961232e-05 | S3: =Q3*10000 -> 0.03168144 | T3: =R3*10000 -> 0.1961232 | U3: 13 | V3: =J3/U3 -> 0.38683077 | W3: =S3/U3 -> 0.0024370338 | X3: =T3/U3 -> 0.0150864
A4: 1 | B4: 1 | C4: 1 | D4: 1 | E4: C | F4: 81.8 | G4: 6.0632 | H4: 1.1061 | I4: =H4/1875 -> 0.00058992 | J4: =I4*10000 -> 5.8992 | K4: 7.1 | L4: 1.3 | M4: 0.88 | N4: 0.16 | O4: 8.8 | P4: 1.6 | Q4: =((M4/100)*H4)/1875 -> 5.191296e-06 | R4: =((K4/100)*H4)/1875 -> 4.188432e-05 | S4: =Q4*10000 -> 0.05191296 | T4: =R4*10000 -> 0.4188432 | U4: 13 | V4: =J4/U4 -> 0.45378462 | W4: =S4/U4 -> 0.0039933046 | X4: =T4/U4 -> 0.032218708
A5: 1 | B5: 1 | C5: 1 | D5: 2 | E5: A | F5: 92.4 | G5: 13.9929 | H5: 1.0683 | I5: =H5/1875 -> 0.00056976 | J5: =I5*10000 -> 5.6976 | K5: 4.7 | L5: 0.4 | M5: 0.83 | N5: 0.06 | O5: 8.3 | P5: 0.63 | Q5: =((M5/100)*H5)/1875 -> 4.729008e-06 | R5: =((K5/100)*H5)/1875 -> 2.677872e-05 | S5: =Q5*10000 -> 0.04729008 | T5: =R5*10000 -> 0.2677872 | U5: 13 | V5: =J5/U5 -> 0.43827692 | W5: =S5/U5 -> 0.0036376985 | X5: =T5/U5 -> 0.020599015
A6: 1 | B6: 1 | C6: 1 | D6: 2 | E6: B | F6: 91.5 | G6: 11.2767 | H6: 0.9635 | I6: =H6/1875 -> 0.00051386667 | J6: =I6*10000 -> 5.1386667 | K6: 6.5 | L6: 0.6 | M6: 0.85 | N6: 0.07 | O6: 8.5 | P6: 0.72 | Q6: =((M6/100)*H6)/1875 -> 4.3678667e-06 | R6: =((K6/100)*H6)/1875 -> 3.3401333e-05 | S6: =Q6*10000 -> 0.043678667 | T6: =R6*10000 -> 0.33401333 | U6: 13 | V6: =J6/U6 -> 0.39528205 | W6: =S6/U6 -> 0.0033598974 | X6: =T6/U6 -> 0.025693333
A7: 1 | B7: 1 | C7: 1 | D7: 2 | E7: C | F7: 95.2 | G7: 15.2101 | H7: 0.7287 | I7: =H7/1875 -> 0.00038864 | J7: =I7*10000 -> 3.8864 | K7: 5.2 | L7: 0.2 | M7: 0.82 | N7: 0.04 | O7: 8.2 | P7: 0.39 | Q7: =((M7/100)*H7)/1875 -> 3.186848e-06 | R7: =((K7/100)*H7)/1875 -> 2.020928e-05 | S7: =Q7*10000 -> 0.03186848 | T7: =R7*10000 -> 0.2020928 | U7: 13 | V7: =J7/U7 -> 0.29895385 | W7: =S7/U7 -> 0.0024514215 | X7: =T7/U7 -> 0.0155456
A8: 1 | B8: 1 | C8: 2 | D8: 1 | E8: A | F8: 91 | G8: 27.6885 | H8: 2.475 | I8: =H8/1875 -> 0.00132 | J8: =I8*10000 -> 13.2 | K8: 12.1 | L8: 1.1 | M8: 0.92 | N8: 0.08 | O8: 9.2 | P8: 0.83 | Q8: =((M8/100)*H8)/1875 -> 1.2144e-05 | R8: =((K8/100)*H8)/1875 -> 0.00015972 | S8: =Q8*10000 -> 0.12144 | T8: =R8*10000 -> 1.5972 | U8: 32 | V8: =J8/U8 -> 0.4125 | W8: =S8/U8 -> 0.003795 | X8: =T8/U8 -> 0.0499125
A9: 1 | B9: 1 | C9: 2 | D9: 1 | E9: B | F9: 86.5 | G9: 19.7214 | H9: 2.7069 | I9: =H9/1875 -> 0.00144368 | J9: =I9*10000 -> 14.4368 | K9: 6.6 | L9: 0.9 | M9: 0.88 | N9: 0.12 | O9: 8.8 | P9: 1.19 | Q9: =((M9/100)*H9)/1875 -> 1.2704384e-05 | R9: =((K9/100)*H9)/1875 -> 9.528288e-05 | S9: =Q9*10000 -> 0.12704384 | T9: =R9*10000 -> 0.9528288 | U9: 32 | V9: =J9/U9 -> 0.45115 | W9: =S9/U9 -> 0.00397012 | X9: =T9/U9 -> 0.0297759
A10: 1 | B10: 1 | C10: 2 | D10: 1 | E10: C | F10: 81.1 | G10: 17.1498 | H10: 3.1814 | I10: =H10/1875 -> 0.0016967467 | J10: =I10*10000 -> 16.967467 | K10: 7.2 | L10: 1.4 | M10: 0.83 | N10: 0.16 | O10: 8.3 | P10: 1.57 | Q10: =((M10/100)*H10)/1875 -> 1.4082997e-05 | R10: =((K10/100)*H10)/1875 -> 0.00012216576 | S10: =Q10*10000 -> 0.14082997 | T10: =R10*10000 -> 1.2216576 | U10: 32 | V10: =J10/U10 -> 0.53023333 | W10: =S10/U10 -> 0.0044009367 | X10: =T10/U10 -> 0.0381768
A11: 1 | B11: 1 | C11: 2 | D11: 2 | E11: A | F11: 89.3 | G11: 40.8474 | H11: 4.3689 | I11: =H11/1875 -> 0.00233008 | J11: =I11*10000 -> 23.3008 | K11: 11.9 | L11: 1.3 | M11: 1.11 | N11: 0.12 | O11: 11.1 | P11: 1.2 | Q11: =((M11/100)*H11)/1875 -> 2.5863888e-05 | R11: =((K11/100)*H11)/1875 -> 0.00027727952 | S11: =Q11*10000 -> 0.25863888 | T11: =R11*10000 -> 2.7727952 | U11: 32 | V11: =J11/U11 -> 0.72815 | W11: =S11/U11 -> 0.008082465 | X11: =T11/U11 -> 0.08664985
A12: 1 | B12: 1 | C12: 2 | D12: 2 | E12: B | F12: 86.3 | G12: 24.9392 | H12: 3.4359 | I12: =H12/1875 -> 0.00183248 | J12: =I12*10000 -> 18.3248 | K12: 5.1 | L12: 0.7 | M12: 1.19 | N12: 0.16 | O12: 11.9 | P12: 1.63 | Q12: =((M12/100)*H12)/1875 -> 2.1806512e-05 | R12: =((K12/100)*H12)/1875 -> 9.345648e-05 | S12: =Q12*10000 -> 0.21806512 | T12: =R12*10000 -> 0.9345648 | U12: 32 | V12: =J12/U12 -> 0.57265 | W12: =S12/U12 -> 0.006814535 | X12: =T12/U12 -> 0.02920515
A13: 1 | B13: 1 | C13: 2 | D13: 2 | E13: C | F13: 80.5 | G13: 22.0238 | H13: 4.3205 | I13: =H13/1875 -> 0.0023042667 | J13: =I13*10000 -> 23.042667 | K13: 13.4 | L13: 2.6 | M13: 0.89 | N13: 0.17 | O13: 8.9 | P13: 1.73 | Q13: =((M13/100)*H13)/1875 -> 2.0507973e-05 | R13: =((K13/100)*H13)/1875 -> 0.00030877173 | S13: =Q13*10000 -> 0.20507973 | T13: =R13*10000 -> 3.0877173 | U13: 32 | V13: =J13/U13 -> 0.72008333 | W13: =S13/U13 -> 0.0064087417 | X13: =T13/U13 -> 0.096491167
... A55: 2 | B55: 1 | C55: 3 | D55: 2 | E55: C | F55: 94.1 | G55: 22.3881 | H55: 1.3265 | I55: =H55/1875 -> 0.00070746667 | J55: =I55*10000 -> 7.0746667 | K55: 8.3 | L55: 0.5 | M55: 2.12 | N55: 0.13 | O55: 21.2 | P55: 1.26 | Q55: =((M55/100)*H55)/1875 -> 1.4998293e-05 | R55: =((K55/100)*H55)/1875 -> 5.8719733e-05 | S55: =Q55*10000 -> 0.14998293 | T55: =R55*10000 -> 0.58719733 | U55: 54 | V55: =J55/U55 -> 0.13101235 | W55: =S55/U55 -> 0.0027774617 | X55: =T55/U55 -> 0.010874025
A56: 2 | B56: 2 | C56: 1 | D56: 1 | E56: A | F56: 97.8 | G56: 5.6249 | H56: 0.1258 | I56: =H56/1875 -> 6.7093333e-05 | J56: =I56*10000 -> 0.67093333 | K56: 1.25 | M56: 0.08 | N56: 0 | O56: 0.8 | P56: 0.02 | Q56: =((M56/100)*H56)/1875 -> 5.3674667e-08 | R56: =((K56/100)*H56)/1875 -> 8.3866667e-07 | S56: =Q56*10000 -> 0.00053674667 | T56: =R56*10000 -> 0.0083866667 | U56: 13 | V56: =J56/U56 -> 0.051610256 | W56: =S56/U56 -> 4.1288205e-05 | X56: =T56/U56 -> 0.00064512821
A57: 2 | B57: 2 | C57: 1 | D57: 1 | E57: B | F57: 97.9 | G57: 5.1266 | H57: 0.1095 | I57: =H57/1875 -> 5.84e-05 | J57: =I57*10000 -> 0.584 | K57: 3.1 | L57: 0.1 | M57: 0.17 | N57: 0 | O57: 1.7 | P57: 0.04 | Q57: =((M57/100)*H57)/1875 -> 9.928e-08 | R57: =((K57/100)*H57)/1875 -> 1.8104e-06 | S57: =Q57*10000 -> 0.0009928 | T57: =R57*10000 -> 0.018104 | U57: 13 | V57: =J57/U57 -> 0.044923077 | W57: =S57/U57 -> 7.6369231e-05 | X57: =T57/U57 -> 0.0013926154
A58: 2 | B58: 2 | C58: 1 | D58: 1 | E58: C | F58: 98.1 | G58: 5.6687 | H58: 0.1061 | I58: =H58/1875 -> 5.6586667e-05 | J58: =I58*10000 -> 0.56586667 | K58: 1.55 | M58: 0.07 | N58: 0 | O58: 0.7 | P58: 0.01 | Q58: =((M58/100)*H58)/1875 -> 3.9610667e-08 | R58: =((K58/100)*H58)/1875 -> 8.7709333e-07 | S58: =Q58*10000 -> 0.00039610667 | T58: =R58*10000 -> 0.0087709333 | U58: 13 | V58: =J58/U58 -> 0.043528205 | W58: =S58/U58 -> 3.0469744e-05 | X58: =T58/U58 -> 0.00067468718
A59: 2 | B59: 2 | C59: 1 | D59: 2 | E59: A | F59: 98.2 | G59: 5.3324 | H59: 0.0964 | I59: =H59/1875 -> 5.1413333e-05 | J59: =I59*10000 -> 0.51413333 | K59: 4.4 | L59: 0.1 | M59: 0.2 | N59: 0 | O59: 2 | P59: 0.04 | Q59: =((M59/100)*H59)/1875 -> 1.0282667e-07 | R59: =((K59/100)*H59)/1875 -> 2.2621867e-06 | S59: =Q59*10000 -> 0.0010282667 | T59: =R59*10000 -> 0.022621867 | U59: 13 | V59: =J59/U59 -> 0.039548718 | W59: =S59/U59 -> 7.9097436e-05 | X59: =T59/U59 -> 0.0017401436
A60: 2 | B60: 2 | C60: 1 | D60: 2 | E60: B | F60: 98.1 | G60: 7.009 | H60: 0.1343 | I60: =H60/1875 -> 7.1626667e-05 | J60: =I60*10000 -> 0.71626667 | K60: 6.1 | L60: 0.1 | M60: 0.39 | N60: 0.01 | O60: 3.9 | P60: 0.07 | Q60: =((M60/100)*H60)/1875 -> 2.79344e-07 | R60: =((K60/100)*H60)/1875 -> 4.3692267e-06 | S60: =Q60*10000 -> 0.00279344 | T60: =R60*10000 -> 0.043692267 | U60: 13 | V60: =J60/U60 -> 0.055097436 | W60: =S60/U60 -> 0.00021488 | X60: =T60/U60 -> 0.0033609436
A61: 2 | B61: 2 | C61: 1 | D61: 2 | E61: C | F61: 98.6 | G61: 4.851 | H61: 0.0659 | I61: =H61/1875 -> 3.5146667e-05 | J61: =I61*10000 -> 0.35146667 | K61: 2.8 | L61: 0 | M61: 0.09 | N61: 0 | O61: 0.9 | P61: 0.01 | Q61: =((M61/100)*H61)/1875 -> 3.1632e-08 | R61: =((K61/100)*H61)/1875 -> 9.8410667e-07 | S61: =Q61*10000 -> 0.00031632 | T61: =R61*10000 -> 0.0098410667 | U61: 13 | V61: =J61/U61 -> 0.027035897 | W61: =S61/U61 -> 2.4332308e-05 | X61: =T61/U61 -> 0.00075700513
A62: 2 | B62: 2 | C62: 2 | D62: 1 | E62: A | F62: 94.5 | G62: 17.7457 | H62: 0.9828 | I62: =H62/1875 -> 0.00052416 | J62: =I62*10000 -> 5.2416 | K62: 9 | L62: 0.5 | M62: 1.24 | N62: 0.07 | O62: 12.4 | P62: 0.69 | Q62: =((M62/100)*H62)/1875 -> 6.499584e-06 | R62: =((K62/100)*H62)/1875 -> 4.71744e-05 | S62: =Q62*10000 -> 0.06499584 | T62: =R62*10000 -> 0.471744 | U62: 32 | V62: =J62/U62 -> 0.1638 | W62: =S62/U62 -> 0.00203112 | X62: =T62/U62 -> 0.014742
A63: 2 | B63: 2 | C63: 2 | D63: 1 | E63: B | F63: 94.9 | G63: 18.6773 | H63: 0.9618 | I63: =H63/1875 -> 0.00051296 | J63: =I63*10000 -> 5.1296 | K63: 8.4 | L63: 0.4 | M63: 1.03 | N63: 0.05 | O63: 10.3 | P63: 0.53 | Q63: =((M63/100)*H63)/1875 -> 5.283488e-06 | R63: =((K63/100)*H63)/1875 -> 4.308864e-05 | S63: =Q63*10000 -> 0.05283488 | T63: =R63*10000 -> 0.4308864 | U63: 32 | V63: =J63/U63 -> 0.1603 | W63: =S63/U63 -> 0.00165109 | X63: =T63/U63 -> 0.0134652
A64: 2 | B64: 2 | C64: 2 | D64: 1 | E64: C | F64: 94 | G64: 14.8309 | H64: 0.8838 | I64: =H64/1875 -> 0.00047136 | J64: =I64*10000 -> 4.7136 | K64: 11.1 | L64: 0.7 | M64: 1.33 | N64: 0.08 | O64: 13.3 | P64: 0.79 | Q64: =((M64/100)*H64)/1875 -> 6.269088e-06 | R64: =((K64/100)*H64)/1875 -> 5.232096e-05 | S64: =Q64*10000 -> 0.06269088 | T64: =R64*10000 -> 0.5232096 | U64: 32 | V64: =J64/U64 -> 0.1473 | W64: =S64/U64 -> 0.00195909 | X64: =T64/U64 -> 0.0163503
A65: 2 | B65: 2 | C65: 2 | D65: 2 | E65: A | F65: 93.5 | G65: 23.0779 | H65: 1.4941 | I65: =H65/1875 -> 0.00079685333 | J65: =I65*10000 -> 7.9685333 | K65: 9.9 | L65: 0.6 | M65: 1.59 | N65: 0.1 | O65: 15.9 | P65: 1.03 | Q65: =((M65/100)*H65)/1875 -> 1.2669968e-05 | R65: =((K65/100)*H65)/1875 -> 7.888848e-05 | S65: =Q65*10000 -> 0.12669968 | T65: =R65*10000 -> 0.7888848 | U65: 32 | V65: =J65/U65 -> 0.24901667 | W65: =S65/U65 -> 0.003959365 | X65: =T65/U65 -> 0.02465265
A66: 2 | B66: 2 | C66: 2 | D66: 2 | E66: B | F66: 93 | G66: 17.7252 | H66: 1.242 | I66: =H66/1875 -> 0.0006624 | J66: =I66*10000 -> 6.624 | K66: 10.6 | L66: 0.7 | M66: 1.91 | N66: 0.13 | O66: 19.1 | P66: 1.34 | Q66: =((M66/100)*H66)/1875 -> 1.265184e-05 | R66: =((K66/100)*H66)/1875 -> 7.02144e-05 | S66: =Q66*10000 -> 0.1265184 | T66: =R66*10000 -> 0.702144 | U66: 32 | V66: =J66/U66 -> 0.207 | W66: =S66/U66 -> 0.0039537 | X66: =T66/U66 -> 0.021942
A67: 2 | B67: 2 | C67: 2 | D67: 2 | E67: C | F67: 94.6 | G67: 20.823 | H67: 1.1323 | I67: =H67/1875 -> 0.00060389333 | J67: =I67*10000 -> 6.0389333 | K67: 10.2 | L67: 0.6 | M67: 1.84 | N67: 0.1 | O67: 18.4 | P67: 1 | Q67: =((M67/100)*H67)/1875 -> 1.1111637e-05 | R67: =((K67/100)*H67)/1875 -> 6.159712e-05 | S67: =Q67*10000 -> 0.11111637 | T67: =R67*10000 -> 0.6159712 | U67: 32 | V67: =J67/U67 -> 0.18871667 | W67: =S67/U67 -> 0.0034723867 | X67: =T67/U67 -> 0.0192491
A68: 2 | B68: 2 | C68: 3 | D68: 1 | E68: A | F68: 92.9 | G68: 20.6185 | H68: 1.4636 | I68: =H68/1875 -> 0.00078058667 | J68: =I68*10000 -> 7.8058667 | K68: 8.7 | L68: 0.6 | M68: 1.91 | N68: 0.14 | O68: 19.1 | P68: 1.36 | Q68: =((M68/100)*H68)/1875 -> 1.4909205e-05 | R68: =((K68/100)*H68)/1875 -> 6.791104e-05 | S68: =Q68*10000 -> 0.14909205 | T68: =R68*10000 -> 0.6791104 | U68: 54 | V68: =J68/U68 -> 0.14455309 | W68: =S68/U68 -> 0.002760964 | X68: =T68/U68 -> 0.012576119
A69: 2 | B69: 2 | C69: 3 | D69: 1 | E69: B | F69: 93.7 | G69: 30.403 | H69: 1.9176 | I69: =H69/1875 -> 0.00102272 | J69: =I69*10000 -> 10.2272 | K69: 9.7 | L69: 0.6 | M69: 1.88 | N69: 0.12 | O69: 18.8 | P69: 1.18 | Q69: =((M69/100)*H69)/1875 -> 1.9227136e-05 | R69: =((K69/100)*H69)/1875 -> 9.920384e-05 | S69: =Q69*10000 -> 0.19227136 | T69: =R69*10000 -> 0.9920384 | U69: 54 | V69: =J69/U69 -> 0.18939259 | W69: =S69/U69 -> 0.0035605807 | X69: =T69/U69 -> 0.018371081
A70: 2 | B70: 2 | C70: 3 | D70: 1 | E70: C | F70: 96.4 | G70: 38.6346 | H70: 1.3943 | I70: =H70/1875 -> 0.00074362667 | J70: =I70*10000 -> 7.4362667 | K70: 6.4 | L70: 0.2 | M70: 1.17 | N70: 0.04 | O70: 11.7 | P70: 0.42 | Q70: =((M70/100)*H70)/1875 -> 8.700432e-06 | R70: =((K70/100)*H70)/1875 -> 4.7592107e-05 | S70: =Q70*10000 -> 0.08700432 | T70: =R70*10000 -> 0.47592107 | U70: 54 | V70: =J70/U70 -> 0.13770864 | W70: =S70/U70 -> 0.0016111911 | X70: =T70/U70 -> 0.0088133531
... A73: 2 | B73: 2 | C73: 3 | D73: 2 | E73: C | F73: 94.4 | G73: 23.2026 | H73: 1.2915 | I73: =H73/1875 -> 0.0006888 | J73: =I73*10000 -> 6.888 | K73: 9.1 | L73: 0.5 | M73: 1.6 | N73: 0.09 | O73: 16 | P73: 0.89 | Q73: =((M73/100)*H73)/1875 -> 1.10208e-05 | R73: =((K73/100)*H73)/1875 -> 6.26808e-05 | S73: =Q73*10000 -> 0.110208 | T73: =R73*10000 -> 0.626808 | U73: 54 | V73: =J73/U73 -> 0.12755556 | W73: =S73/U73 -> 0.0020408889 | X73: =T73/U73 -> 0.011607556

Sheet Sheet3
E2: Season | F2: Fixed | G2: 1 = High growth | I2: Settlement plate size = 37.5 x 50 cm | M2: =37.5*50 -> 1875
G3: 2 = Low growth
E5: Age | F5: Fixed | G5: 1 = 13 days
G6: 2 = 32 days
G7: 3 = 54 days
E9: Location | F9: Random | G9: 1=Berth C
G10: 2=Berth G
I12: Dry weight (g)
I13: Season | J13: Time (d) | K13: Average | L13: SE
I14: Summer | J14: 13 | K14: =AVERAGE(Sheet1!$H$2:$H$7,Sheet1!$H$20:$H$25) -> 0.82983333 | L14: =STDEV(Sheet1!$H$2:$H$7,Sheet1!$H$20:$H$25)/SQRT(6) -> 0.085092277
I15: Summer | J15: 32 | K15: =AVERAGE(Sheet1!$H$8:$H$13,Sheet1!$H$26:$H$31) -> 3.5931833 | L15: =STDEV(Sheet1!$H$8:$H$13,Sheet1!$H$26:$H$31)/SQRT(6) -> 0.28794309
I16: Summer | J16: 54 | K16: =AVERAGE(Sheet1!$H$14:$H$19,Sheet1!$H$32:$H$37) -> 15.348567 | L16: =STDEV(Sheet1!$H$14:$H$19,Sheet1!$H$32:$H$37)/SQRT(6) -> 1.4893379
I17: Winter | J17: 13 | K17: =AVERAGE(Sheet1!$H$38:$H$43,Sheet1!$H$56:$H$61) -> 0.139625 | L17: =STDEV(Sheet1!$H$38:$H$43,Sheet1!$H$56:$H$61)/SQRT(6) -> 0.01846576
I18: Winter | J18: 32 | K18: =AVERAGE(Sheet1!$H$44:$H$49,Sheet1!$H$62:$H$67) -> 1.0521083 | L18: =STDEV(Sheet1!$H$44:$H$49,Sheet1!$H$62:$H$67)/SQRT(6) -> 0.074268562
I19: Winter | J19: 54 | K19: =AVERAGE(Sheet1!$H$50:$H$55,Sheet1!$H$68:$H$73) -> 1.5005083 | L19: =STDEV(Sheet1!$H$50:$H$55,Sheet1!$H$68:$H$73)/SQRT(6) -> 0.074669787
I28: Protein g/100g dry weight
I29: Season | J29: Time | K29: Average | L29: SE
I30: Summer | J30: 13 | K30: =AVERAGE(Sheet1!$T$2:$T$7,Sheet1!$T$20:$T$25) -> 0.22614804 | L30: =STDEV(Sheet1!$T$2:$T$7,Sheet1!$T$20:$T$25)/SQRT(6) -> 0.034028856
J31: 32 | K31: =AVERAGE(Sheet1!$T$8:$T$13,Sheet1!$T$26:$T$31) -> 1.5253444 | L31: =STDEV(Sheet1!$T$8:$T$13,Sheet1!$T$26:$T$31)/SQRT(6) -> 0.302564
J32: 54 | K32: =AVERAGE(Sheet1!$T$14:$T$19,Sheet1!$T$32:$T$37) -> 12.576783 | L32: =STDEV(Sheet1!$T$14:$T$19,Sheet1!$T$32:$T$37)/SQRT(6) -> 2.3158446
I33: Winter | J33: 13 | K33: =AVERAGE(Sheet1!$T$38:$T$43,Sheet1!$T$56:$T$61) -> 0.019523178 | L33: =STDEV(Sheet1!$T$38:$T$43,Sheet1!$T$56:$T$61)/SQRT(6) -> 0.0045846245
J34: 32 | K34: =AVERAGE(Sheet1!$T$44:$T$49,Sheet1!$T$62:$T$67) -> 0.55023938 | L34: =STDEV(Sheet1!$T$44:$T$49,Sheet1!$T$62:$T$67)/SQRT(6) -> 0.044295869
J35: 54 | K35: =AVERAGE(Sheet1!$T$50:$T$55,Sheet1!$T$68:$T$73) -> 0.73474769 | L35: =STDEV(Sheet1!$T$50:$T$55,Sheet1!$T$68:$T$73)/SQRT(6) -> 0.064715413
I43: fat g/100g dry weight
I44: Season | J44: Time | K44: Average | L44: SE
I45: Summer | J45: 13 | K45: =AVERAGE(Sheet1!$S$2:$S$7,Sheet1!$S$20:$S$25) -> 0.036661818 | L45: =STDEV(Sheet1!$S$2:$S$7,Sheet1!$S$20:$S$25)/SQRT(6) -> 0.0045860183
J46: 32 | K46: =AVERAGE(Sheet1!$S$8:$S$13,Sheet1!$S$26:$S$31) -> 0.15054209 | L46: =STDEV(Sheet1!$S$8:$S$13,Sheet1!$S$26:$S$31)/SQRT(6) -> 0.020169876
J47: 54 | K47: =AVERAGE(Sheet1!$S$14:$S$19,Sheet1!$S$32:$S$37) -> 0.57312792 | L47: =STDEV(Sheet1!$S$14:$S$19,Sheet1!$S$32:$S$37)/SQRT(6) -> 0.067599391
I48: Winter | J48: 13 | K48: =AVERAGE(Sheet1!$S$38:$S$43,Sheet1!$S$56:$S$61) -> 0.0013665244 | L48: =STDEV(Sheet1!$S$38:$S$43,Sheet1!$S$56:$S$61)/SQRT(6) -> 0.00039016098
J49: 32 | K49: =AVERAGE(Sheet1!$S$44:$S$49,Sheet1!$S$62:$S$67) -> 0.089206018 | L49: =STDEV(Sheet1!$S$44:$S$49,Sheet1!$S$62:$S$67)/SQRT(6) -> 0.010058451
J50: 54 | K50: =AVERAGE(Sheet1!$S$50:$S$55,Sheet1!$S$68:$S$73) -> 0.12941468 | L50: =STDEV(Sheet1!$S$50:$S$55,Sheet1!$S$68:$S$73)/SQRT(6) -> 0.012047637
I65: average dry weight accumulation (g/m2/day)
I66: Season | J66: Time | K66: Average | L66: SE
I67: Summer | J67: 13 | K67: =AVERAGE(Sheet1!$V$2:$V$7,Sheet1!$V$20:$V$25) -> 0.34044444 | L67: =STDEV(Sheet1!$V$2:$V$7,Sheet1!$V$20:$V$25)/SQRT(6) -> 0.034909652
J68: 32 | K68: =AVERAGE(Sheet1!$V$8:$V$13,Sheet1!$V$26:$V$31) -> 0.59886389 | L68: =STDEV(Sheet1!$V$8:$V$13,Sheet1!$V$26:$V$31)/SQRT(6) -> 0.047990516
J69: 54 | K69: =AVERAGE(Sheet1!$V$14:$V$19,Sheet1!$V$32:$V$37) -> 1.5159078 | L69: =STDEV(Sheet1!$V$14:$V$19,Sheet1!$V$32:$V$37)/SQRT(6) -> 0.1470951
I70: Winter | J70: 13 | K70: =AVERAGE(Sheet1!$V$38:$V$43,Sheet1!$V$56:$V$61) -> 0.057282051 | L70: =STDEV(Sheet1!$V$38:$V$43,Sheet1!$V$56:$V$61)/SQRT(6) -> 0.0075756963
J71: 32 | K71: =AVERAGE(Sheet1!$V$44:$V$49,Sheet1!$V$62:$V$67) -> 0.17535139 | L71: =STDEV(Sheet1!$V$44:$V$49,Sheet1!$V$62:$V$67)/SQRT(6) -> 0.012378094
J72: 54 | K72: =AVERAGE(Sheet1!$V$50:$V$55,Sheet1!$V$68:$V$73) -> 0.14819835 | L72: =STDEV(Sheet1!$V$50:$V$55,Sheet1!$V$68:$V$73)/SQRT(6) -> 0.0073747938
I83: average daily fat accumulation (g/m2/day)
...

Sheet Sheet2
B1: Occlusion (proportion) | C1: Area | D1: Radius | E1: Fouling thickness
B2: 0 | C2: =H4 -> 49087.386 | D2: =SQRT(C2/$H$2) -> 125 | E2: =$H$3-D2 -> 0 | G2: pi | H2: =3.1415927 -> 3.1415927
B3: 0.1 | C3: =C2-($C$2*$B$3) -> 44178.647 | D3: =SQRT(C3/$H$2) -> 118.58541 | E3: =$H$3-D3 -> 6.4145877 | G3: radius | H3: 125
B4: 0.2 | C4: =C3-($C$2*$B$3) -> 39269.909 | D4: =SQRT(C4/$H$2) -> 111.8034 | E4: =$H$3-D4 -> 13.196601 | G4: Area | H4: =H2*(H3*H3) -> 49087.386
B5: 0.3 | C5: =C4-($C$2*$B$3) -> 34361.17 | D5: =SQRT(C5/$H$2) -> 104.5825 | E5: =$H$3-D5 -> 20.417497
B6: 0.4 | C6: =C5-($C$2*$B$3) -> 29452.432 | D6: =SQRT(C6/$H$2) -> 96.824584 | E6: =$H$3-D6 -> 28.175416
B7: 0.5 | C7: =C6-($C$2*$B$3) -> 24543.693 | D7: =SQRT(C7/$H$2) -> 88.388348 | E7: =$H$3-D7 -> 36.611652
B8: 0.6 | C8: =C7-($C$2*$B$3) -> 19634.954 | D8: =SQRT(C8/$H$2) -> 79.056942 | E8: =$H$3-D8 -> 45.943058
B9: 0.7 | C9: =C8-($C$2*$B$3) -> 14726.216 | D9: =SQRT(C9/$H$2) -> 68.46532 | E9: =$H$3-D9 -> 56.53468
B10: 0.8 | C10: =C9-($C$2*$B$3) -> 9817.4772 | D10: =SQRT(C10/$H$2) -> 55.901699 | E10: =$H$3-D10 -> 69.098301
B11: 0.9 | C11: =C10-($C$2*$B$3) -> 4908.7386 | D11: =SQRT(C11/$H$2) -> 39.528471 | E11: =$H$3-D11 -> 85.471529
B12: 1 | C12: =C11-($C$2*$B$3) -> 0 | D12: =SQRT(C12/$H$2) -> 0 | E12: =$H$3-D12 -> 125
